<?xml version="1.0"?>
<robot xmlns:xacro="http://www.ros.org/wiki/xacro">

    <xacro:include filename="inertial_macros.xacro"/>

    <material name="white">
        <color rgba="1 1 1 1"/>
    </material>

    <material name="orange">
        <color rgba="1 0.3 0.1 1"/>
    </material>

    <material name="blue">
        <color rgba="0.2 0.2 1 1"/>
    </material>

    <material name="black">
        <color rgba="0 0 0 1"/>
    </material>

    <material name="red">
        <color rgba="1 0 0 1"/>
    </material>

    <!-- ___________________________________ colors ________________________________ -->
    
    <link name="world">
    </link>

    <link name="base">
        <visual>
            <origin xyz="0 0 0.0225"/>
            <geometry>
                <cylinder radius="0.0475" length="0.045"/>
            </geometry>
            <material name="blue"/>
        </visual>
        <collision>
            <origin xyz="0 0 0.0225"/>
            <geometry>
                <cylinder radius="0.0475" length="0.045"/>
            </geometry>
        </collision>
        <xacro:inertial_cylinder mass="0.5" radius="0.0475" length="0.045">
            <origin xyz="0 0 0" rpy="0 0 0"/>
        </xacro:inertial_cylinder>
    </link>

    <joint name="world_joint" type="fixed">
        <parent link="world"/>
        <child link="base"/>
        <origin xyz="0 0 0"/>
    </joint>

    <!-- _________________________________ Base ___________________________ -->


    <joint name="rot_base_joint" type="revolute">
        <parent link="base"/>
        <child link="rot_base"/>
        <origin xyz="0 0 0.045"/>
        <axis xyz="0 0 1"/>
        <limit lower="-${pi/2}" upper="${pi/2}" effort="100" velocity="0.2"/>
    </joint>

    <link name="rot_base">
        <visual>
            <origin xyz="0 0 0.005"/>
            <geometry>
                <cylinder radius="0.0475" length="0.01"/>
            </geometry>
            <material name="white"/>
        </visual>
        <collision>
            <origin xyz="0 0 0.005"/>
            <geometry>
                <cylinder radius="0.0475" length="0.01"/>
            </geometry>
        </collision>
        <xacro:inertial_cylinder mass="0.2" radius="0.0475" length="0.01">
            <origin xyz="0 0 0" rpy="0 0 0"/>
        </xacro:inertial_cylinder>
    </link>

    <joint name="arm1_motor_joint" type="fixed">
        <parent link="rot_base"/>
        <child link="arm1_motor"/>
        <origin xyz="0 0 0.01"/>
    </joint>

    <link name="arm1_motor">
        <visual>
            <origin xyz="0 0 0.015"/>
            <geometry>
                <box size="0.064 0.04 0.03"/>
            </geometry>
            <material name="blue"/>
        </visual>
        <collision>
            <origin xyz="0 0 0.015"/>
            <geometry>
                <box size="0.064 0.04 0.03"/>
            </geometry>
        </collision>
        <xacro:inertial_box mass="0.5" x="0.04"  y="0.04" z="0.03">
            <origin xyz="0 0 0" rpy="0 0 0"/>
        </xacro:inertial_box>
    </link>

    <!-- ____________________________ Arm1 ______________________ -->

    <link name="arm1_bracket">
        <visual>
            <origin xyz="-0.068 0.0125 0.0745" rpy="${pi} 0 0"/>
            <geometry>
                <mesh filename="package://demo_arm/meshes/arm1_bracket.stl" scale="0.001 0.001 0.001"/>
            </geometry>
            <material name="black"/>
        </visual>
        <collision>
            <origin xyz="-0.068 0.0125 0.0745" rpy="${pi} 0 0"/>
            <geometry>
                <mesh filename="package://demo_arm/meshes/arm1_bracket.stl" scale="0.001 0.001 0.001"/> 
            </geometry>
        </collision>
    </link>

    <joint name="arm1_joint" type="revolute">
        <parent link="arm1_motor"/>
        <child link="arm1_bracket"/>
        <origin xyz="0.034 -0.014 0.022" rpy="0 0 0"/>
        <axis xyz="1 0 0" rpy="0 0 0"/>
        <limit lower="-${pi/2}" upper="${pi/2}" effort="100" velocity="0.2"/>
    </joint>

    <!-- ___________________________ Arm2 _______________________________ -->

    <link name="arm2_bracket">
        <visual>
            <origin xyz="-0.0265 -0.0125 0"/>
            <geometry>
                <mesh filename="package://demo_arm/meshes/arm2_bracket.stl" scale="0.001 0.001 0.001"/>
            </geometry>
            <material name="black"/>
        </visual>
        <collision>
            <origin xyz="-0.0265 -0.0125 0"/>
            <geometry>
                <mesh filename="package://demo_arm/meshes/arm2_bracket.stl" scale="0.001 0.001 0.001"/> 
            </geometry>
        </collision>
    </link>

    <joint name="arm_bracket_joint" type="fixed">
        <parent link="arm1_bracket"/>
        <child link="arm2_bracket"/>
        <origin xyz="-0.034 0 0.0745"/>
    </joint>

    <link name="arm2_motor">
        <visual>
            <origin xyz="-0.026 0 -0.01"/>
            <geometry>
                <box size="0.049 0.025 0.04"/>
            </geometry>
            <material name="blue"/>
        </visual>
        <collision>
            <origin xyz="-0.026 0 -0.01"/>
            <geometry>
                <box size="0.049 0.025 0.04"/>
            </geometry>
        </collision>
        <xacro:inertial_box mass="0.5" x="0.04"  y="0.04" z="0.03">
            <origin xyz="0 0 0" rpy="0 0 0"/>
        </xacro:inertial_box>
    </link>

    <joint name="arm2_joint" type="revolute">
        <parent link="arm2_bracket"/>
        <child link="arm2_motor"/>
        <origin xyz="0.026 0 0.044"/>
        <axis xyz="1 0 0" rpy="0 0 0"/>
        <limit lower="-${pi/2}" upper="${pi/2}" effort="100" velocity="0.2"/>
    </joint>

    <link name="arm2_stem">
        <visual>
            <origin xyz="0 0 0"/>
            <geometry>
                <mesh filename="package://demo_arm/meshes/arm2_stem.stl" scale="0.001 0.001 0.001"/>
            </geometry>
            <material name="white"/>
        </visual>
        <collision>
            <origin xyz="0 0 0"/>
            <geometry>
                <mesh filename="package://demo_arm/meshes/arm2_stem.stl" scale="0.001 0.001 0.001"/> 
            </geometry>
        </collision>
    </link>

    <joint name="arm2_stem_joint" type="fixed">
        <parent link="arm2_motor"/>
        <child link="arm2_stem"/>
        <origin xyz="-0.0245 0 0.01"/>
    </joint>

    <!-- _____________________________ Arm3 ______________________________ -->

    <link name="arm3_motor">
        <visual>
            <origin xyz="0 0 0.02"/>
            <geometry>
                <box size="0.048 0.025 0.04"/>
            </geometry>
            <material name="blue"/>
        </visual>
        <collision>
            <origin xyz="0 0 0.02"/>
            <geometry>
                <box size="0.048 0.025 0.04"/>
            </geometry>
        </collision>
        <xacro:inertial_box mass="0.5" x="0.04"  y="0.04" z="0.03">
            <origin xyz="0 0 0" rpy="0 0 0"/>
        </xacro:inertial_box>
    </link>

    <joint name="arm3_motor_joint" type="fixed">
        <parent link="arm2_stem"/>
        <child link="arm3_motor"/>
        <origin xyz="0 0 0.07"/>
    </joint>

    <link name="arm3_bracket">
        <visual>
            <origin xyz="-0.05 0.0125 0.0415" rpy="${pi} 0 0"/>
            <geometry>
                <mesh filename="package://demo_arm/meshes/arm3_bracket.stl" scale="0.001 0.001 0.001"/>
            </geometry>
            <material name="black"/>
        </visual>
        <collision>
            <origin xyz="-0.5 0.0125 0.0415" rpy="${pi} 0 0"/>
            <geometry>
                <mesh filename="package://demo_arm/meshes/arm3_bracket.stl" scale="0.001 0.001 0.001"/> 
            </geometry>
        </collision>
    </link>

    <joint name="arm3_joint" type="revolute">
        <parent link="arm3_motor"/>
        <child link="arm3_bracket"/>
        <origin xyz="0.024 0 0.035"/>
        <axis xyz="1 0 0" rpy="0 0 0"/>
        <limit lower="-${pi/2}" upper="${pi/2}" effort="100" velocity="0.2"/>
    </joint>


</robot>